Workbook
Name Slicer_Category: #N/A
Name Slicer_Stock_Status: #N/A
Name Slicer_Supplier: #N/A

Sheet Project Overview
A1: INVENTORY AND SUPPLY CHAIN ANALYTICS PROJECT
A4: PROJECT INFORMATION
A6: Project Title :
A7: Inventory and Supply Chain Analytics Dashboard
A9: Prepared By :
A10: Parismita Pathak
A12: Tools Used :
A13: Microsoft Excel
A15: Project Type :
A16: Inventory Analytics and Supply Chain Management
A19: PROJECT OBJECTIVES
A21: • To analyze inventory distribution across product categories
... A42: WORKBOOK CONTENTS
A44: Sheet Name | E44: Purpose
A45: Executive Dashboard | E45: Inventory performance review
A46: ABC Analysis | E46: Inventory classification and prioritization
A47: Category Analysis | E47: Category-wise inventory analysis
A48: Supplier Analysis | E48: Supplier contribution analysis
A49: Inventory Turnover Analysis | E49: Fast-moving inventory analysis
A50: Monthly Demand Data | E50: Product demand trend analysis
A51: Forecast Analysis | E51: Demand forecasting
A52: Raw Data | E52: Source inventory dataset
A53: Calculations | E53: Supporting calculations
A56: PROJECT SUMMARY
A58: • This project applies inventory analytics techniques to evaluate stock distribution, supplier performance, inventory turnover, inventory prioritization, and demand forecasting.
A59: • Interactive dashboards and visualizations were developed to support data-driven inventory management and supply chain decision-making.
A62: KEY SKILLS DEMONSTRATED
A64: • Inventory Analytics
A65: • Supply Chain Analytics
A66: • Data Visualization
A67: • KPI Reporting
A68: • Demand Forecasting
A69: • Business Analysis
A70: • Dashboard Development
A71: • Excel Reporting

Sheet Executive Dashboard
I1: Inventory and Supply Chain Dashboard
B5: ='Raw Data'!B47 -> 1925 | D5: ='Raw Data'!B48 -> 40 | F5: ='Raw Data'!B49 -> 4
B6: Total Stock | D6: Total Items | F6: Reorder Items
J37: Executive Summary
J39: • Inventory analysis identified a small group of high-priority products that drive the majority of inventory movement.
J41: • Grocery, Household, and Personal Care categories account for the largest share of inventory holdings.
J43: • Fast-moving products such as Bread, Milk, Potatoes, and Onions require frequent replenishment to maintain availability.
J45: • Demand forecasting indicates stable future demand for key inventory items, supporting proactive inventory planning.

Sheet ABC Analysis
B1: ABC Analysis - Inventory Classification
J5: ABC Category | K5: No. of Items
J6: A | K6: 20
J7: B | K7: 10
J8: C | K8: 10
B23: Insights & Findings
B25: 1. A-category items contribute the highest share of inventory movement and require strict monitoring and frequent replenishment.
B27: 2. B-category items show moderate demand and can be managed using periodic review policies.
B29: 3. C-category items contribute least to movement and can be stocked in bulk with minimal monitoring.
B31: 4. High-demand items such as vegetables, dairy, and beverages are concentrated in A-category, indicating critical supply chain importance.
B33: Key Takeaway
B35: Prioritizing A-category items can significantly reduce stockout risk and improve inventory efficiency.

Sheet Category Analysis
A1: Category-Wise Inventory Analysis
A3: Category | B3: Total Stock Available
A4: Grocery | B4: 370
A5: Household | B5: 300
A6: Personal Care | B6: 300
A7: Dairy | B7: 175
A8: Beverages | B8: 165
A9: Snacks | B9: 145
A10: Frozen Foods | B10: 130
A11: Bakery | B11: 125
A12: Fruits | B12: 90
A13: Vegetables | B13: 85
A14: Packaged Food | B14: 40
A15: Grand Total | B15: 1925
E21: Key Takeaway
E23: Grocery, Household, and Personal Care categories account for the largest share of inventory holdings and require continuous monitoring for optimal stock management.

Sheet Supplier Analysis
A1: Supplier Performance Analysis
A3: Supplier | B3: Total Stock Received
A4: AgroFresh Supplies Pvt Ltd | B4: 490
A5: HygieneCorp Suppliers | B5: 290
A6: FreshFarm Produce Suppliers | B6: 220
A7: HomeCare Essentials Ltd | B7: 210
A8: SpiceRoute Imports | B8: 180
A9: CrunchBake Pvt Ltd | B9: 160
A10: FreshFarm Dairy Ltd | B10: 160
A11: ColdChain Proteins Ltd | B11: 150
A12: BakeHouse Distributors | B12: 150
A13: DairyDelight Suppliers | B13: 140
A14: Grand Total | B14: 2150
E21: Key Takeaway
E23: A small number of suppliers contribute a significant portion of inventory, making supplier performance monitoring essential for supply chain stability.

Sheet Inventory Turnover Analysis
A1: Inventory Turnover Performance Analysis
A3: Item Name | B3: Avg Turnover
A4: Bread | B4: 7
A5: Milk | B5: 5
A6: Potatoes | B6: 3.8
A7: Spinach | B7: 3.5
A8: Eggs | B8: 2.3333333
A9: Onions | B9: 2.25
A10: Fruit Juice | B10: 2
A11: Chips | B11: 2
A12: Handwash | B12: 2
A13: Hand Sanitizer | B13: 1.8571429
E21: Key Takeaway
E23: Fast-moving products such as Bread, Milk, and Potatoes require proactive replenishment planning to maintain product availability.

Sheet Monthly Demand Data
A1: Demand Forecasting Analysis - Potatoes
A3: Item ID | B3: Item Name | C3: Month | D3: Demand | E3: 3-Month Moving Average
A4: I030 | B4: Potatoes | C4: January | D4: 25 | E4: ="" | H4: LATEST DEMAND | J4: JULY FORECAST | L4: DEMAND TREND
A5: I030 | B5: Potatoes | C5: February | D5: 20 | E5: ="" | H5: 10 units | J5: 10 units | L5: Declining
A6: I030 | B6: Potatoes | C6: March | D6: 20 | E6: =ROUND(AVERAGE(D4:D6),2) -> 21.67
A7: I030 | B7: Potatoes | C7: April | D7: 10 | E7: =ROUND(AVERAGE(D5:D7),2) -> 16.67
A8: I030 | B8: Potatoes | C8: May | D8: 10 | E8: =ROUND(AVERAGE(D6:D8),2) -> 13.33
A9: I030 | B9: Potatoes | C9: June | D9: 10 | E9: =ROUND(AVERAGE(D7:D9),2) -> 10
A11: I031 | B11: Onions | C11: January | D11: 30 | E11: NA
A12: I031 | B12: Onions | C12: February | D12: 15 | E12: NA
A13: I031 | B13: Onions | C13: March | D13: 15 | E13: =ROUND(AVERAGE(D11:D13),2) -> 20
A14: I031 | B14: Onions | C14: April | D14: 10 | E14: =ROUND(AVERAGE(D12:D14),2) -> 13.33
A15: I031 | B15: Onions | C15: May | D15: 15 | E15: =ROUND(AVERAGE(D13:D15),2) -> 13.33
A16: I031 | B16: Onions | C16: June | D16: 5 | E16: =ROUND(AVERAGE(D14:D16),2) -> 10
A18: I009 | B18: Fruit Juice | C18: January | D18: 20 | E18: NA
A19: I009 | B19: Fruit Juice | C19: February | D19: 10 | E19: NA
A20: I009 | B20: Fruit Juice | C20: March | D20: 15 | E20: =ROUND(AVERAGE(D18:D20),2) -> 15
A21: I009 | B21: Fruit Juice | C21: April | D21: 15 | E21: =ROUND(AVERAGE(D19:D21),2) -> 13.33
A22: I009 | B22: Fruit Juice | C22: May | D22: 10 | E22: =ROUND(AVERAGE(D20:D22),2) -> 13.33
A23: I009 | B23: Fruit Juice | C23: June | D23: 10 | E23: =ROUND(AVERAGE(D21:D23),2) -> 11.67
A25: I006 | B25: Eggs | C25: January | D25: 15 | E25: NA
A26: I006 | B26: Eggs | C26: February | D26: 10 | E26: NA
A27: I006 | B27: Eggs | C27: March | D27: 10 | E27: =ROUND(AVERAGE(D25:D27),2) -> 11.67
A28: I006 | B28: Eggs | C28: April | D28: 15 | E28: =ROUND(AVERAGE(D26:D28),2) -> 11.67
A29: I006 | B29: Eggs | C29: May | D29: 10 | E29: =ROUND(AVERAGE(D27:D29),2) -> 11.67
A30: I006 | B30: Eggs | C30: June | D30: 10 | E30: =ROUND(AVERAGE(D28:D30),2) -> 11.67
A32: I017 | B32: Mineral Water | C32: January | D32: 15 | E32: NA
A33: I017 | B33: Mineral Water | C33: February | D33: 25 | E33: NA
A34: I017 | B34: Mineral Water | C34: March | D34: 5 | E34: =ROUND(AVERAGE(D32:D34),2) -> 15
A35: I017 | B35: Mineral Water | C35: April | D35: 15 | E35: =ROUND(AVERAGE(D33:D35),2) -> 15
A36: I017 | B36: Mineral Water | C36: May | D36: 5 | E36: =ROUND(AVERAGE(D34:D36),2) -> 8.33
A37: I017 | B37: Mineral Water | C37: June | D37: 10 | E37: =ROUND(AVERAGE(D35:D37),2) -> 10
A39: I032 | B39: Bananas | C39: January | D39: 10 | E39: NA
A40: I032 | B40: Bananas | C40: February | D40: 20 | E40: NA
A41: I032 | B41: Bananas | C41: March | D41: 25 | E41: =ROUND(AVERAGE(D39:D41),2) -> 18.33
A42: I032 | B42: Bananas | C42: April | D42: 5 | E42: =ROUND(AVERAGE(D40:D42),2) -> 16.67
A43: I032 | B43: Bananas | C43: May | D43: 5 | E43: =ROUND(AVERAGE(D41:D43),2) -> 11.67
A44: I032 | B44: Bananas | C44: June | D44: 5 | E44: =ROUND(AVERAGE(D42:D44),2) -> 5
A46: I021 | B46: Handwash | C46: January | D46: 10 | E46: NA
A47: I021 | B47: Handwash | C47: February | D47: 20 | E47: NA
...

Sheet Forecast Analysis
A1: Inventory Demand Forecast Analysis
A3: Sum of Demand | B3: Column Labels | J3: ITEMS ANALYZED | L3: TOTAL DEMAND | N3: TOP DEMAND ITEM | P3: AVG MONTHLY DEMAND
A4: Row Labels | B4: Eggs | C4: Fruit Juice | D4: Handwash | E4: Mineral Water | F4: Onions | G4: Potatoes | H4: Grand Total | J4: 6 | L4: 490 | N4: Potatoes (95) | P4: =ROUND((490/6),2) -> 81.67
A5: January | B5: 15 | C5: 20 | D5: 10 | E5: 15 | F5: 30 | G5: 25 | H5: 115
A6: February | B6: 10 | C6: 10 | D6: 20 | E6: 25 | F6: 15 | G6: 20 | H6: 100
A7: March | B7: 10 | C7: 15 | D7: 25 | E7: 5 | F7: 15 | G7: 20 | H7: 90
A8: April | B8: 15 | C8: 15 | D8: 10 | E8: 15 | F8: 10 | G8: 10 | H8: 75
A9: May | B9: 10 | C9: 10 | D9: 5 | E9: 5 | F9: 15 | G9: 10 | H9: 55
A10: June | B10: 10 | C10: 10 | D10: 10 | E10: 10 | F10: 5 | G10: 10 | H10: 55
A11: Grand Total | B11: 70 | C11: 80 | D11: 80 | E11: 75 | F11: 90 | G11: 95 | H11: 490
B33: Key Findings
B35: • Potatoes recorded the highest cumulative demand (95 units), followed by Onions (90 units), making them the most critical fast-moving inventory items.
B37: • Fruit Juice and Handwash maintained relatively strong demand throughout the six-month period, indicating consistent customer consumption patterns.
B39: • Demand levels generally declined from January–March to May–June across most items, suggesting the need for periodic inventory review and demand monitoring.
B41: • The analysis highlights priority items for replenishment planning and supports inventory optimization decisions.
B44: Key Takeaway
B46: Potatoes and Onions remain the most significant fast-moving products and should be prioritized for inventory planning and replenishment decisions.

Sheet Raw Data
A1: Item ID | B1: Item Name | C1: Category | D1: Subcategory | E1: Stock In | F1: Stock Out | G1: Current Stock | H1: Reorder Level | I1: Supplier | J1: Stock Status | K1: Turnover | L1: Turnover Category | M1: Stock Gap | N1: Stock Health Status
A2: I001 | B2: Rice | C2: Grocery | D2: Staples | E2: 100 | F2: 20 | G2: =E2-F2 -> 80 | H2: 30 | I2: AgroFresh Supplies Pvt Ltd | J2: =IF(G2<H2, "Reorder","OK") -> OK | K2: =F2/G2 -> 0.25 | L2: =IF(K2>1.5,"Fast",IF(K2>=1,"Moderate","Slow")) -> Slow | M2: =G2-H2 -> 50 | N2: =IF(M2<0,"Critical",IF(M2<10,"Low Buffer","Safe")) -> Safe
A3: I002 | B3: Shampoo | C3: Personal Care | D3: Hair Care | E3: 50 | F3: 10 | G3: =E3-F3 -> 40 | H3: 15 | I3: CarePlus Distribution Ltd | J3: =IF(G3<H3, "Reorder","OK") -> OK | K3: =F3/G3 -> 0.25 | L3: =IF(K3>1.5,"Fast",IF(K3>=1,"Moderate","Slow")) -> Slow | M3: =G3-H3 -> 25 | N3: =IF(M3<0,"Critical",IF(M3<10,"Low Buffer","Safe")) -> Safe
A4: I003 | B4: Biscuits | C4: Snacks | D4: Packaged Snacks | E4: 80 | F4: 25 | G4: =E4-F4 -> 55 | H4: 20 | I4: CrunchBake Pvt Ltd | J4: =IF(G4<H4, "Reorder","OK") -> OK | K4: =F4/G4 -> 0.45454545 | L4: =IF(K4>1.5,"Fast",IF(K4>=1,"Moderate","Slow")) -> Slow | M4: =G4-H4 -> 35 | N4: =IF(M4<0,"Critical",IF(M4<10,"Low Buffer","Safe")) -> Safe
A5: I004 | B5: Milk | C5: Dairy | D5: Fresh Dairy | E5: 60 | F5: 50 | G5: =E5-F5 -> 10 | H5: 20 | I5: FreshFarm Dairy Ltd | J5: =IF(G5<H5, "Reorder","OK") -> Reorder | K5: =F5/G5 -> 5 | L5: =IF(K5>1.5,"Fast",IF(K5>=1,"Moderate","Slow")) -> Fast | M5: =G5-H5 -> -10 | N5: =IF(M5<0,"Critical",IF(M5<10,"Low Buffer","Safe")) -> Critical
A6: I005 | B6: Bread | C6: Bakery | D6: Packaged Bakery | E6: 40 | F6: 35 | G6: =E6-F6 -> 5 | H6: 10 | I6: BakeHouse Distributors | J6: =IF(G6<H6, "Reorder","OK") -> Reorder | K6: =F6/G6 -> 7 | L6: =IF(K6>1.5,"Fast",IF(K6>=1,"Moderate","Slow")) -> Fast | M6: =G6-H6 -> -5 | N6: =IF(M6<0,"Critical",IF(M6<10,"Low Buffer","Safe")) -> Critical
A7: I006 | B7: Eggs | C7: Dairy | D7: Poultry Products | E7: 100 | F7: 70 | G7: =E7-F7 -> 30 | H7: 30 | I7: FarmFresh Poultry Ltd | J7: =IF(G7<H7, "Reorder","OK") -> OK | K7: =F7/G7 -> 2.3333333 | L7: =IF(K7>1.5,"Fast",IF(K7>=1,"Moderate","Slow")) -> Fast | M7: =G7-H7 -> 0 | N7: =IF(M7<0,"Critical",IF(M7<10,"Low Buffer","Safe")) -> Low Buffer
A8: I007 | B8: Soap | C8: Personal Care | D8: Body Care | E8: 70 | F8: 30 | G8: =E8-F8 -> 40 | H8: 25 | I8: HygieneCorp Suppliers | J8: =IF(G8<H8, "Reorder","OK") -> OK | K8: =F8/G8 -> 0.75 | L8: =IF(K8>1.5,"Fast",IF(K8>=1,"Moderate","Slow")) -> Slow | M8: =G8-H8 -> 15 | N8: =IF(M8<0,"Critical",IF(M8<10,"Low Buffer","Safe")) -> Safe
A9: I008 | B9: Chips | C9: Snacks | D9: Packaged Snacks | E9: 90 | F9: 60 | G9: =E9-F9 -> 30 | H9: 30 | I9: CrunchTime Foods Ltd | J9: =IF(G9<H9, "Reorder","OK") -> OK | K9: =F9/G9 -> 2 | L9: =IF(K9>1.5,"Fast",IF(K9>=1,"Moderate","Slow")) -> Fast | M9: =G9-H9 -> 0 | N9: =IF(M9<0,"Critical",IF(M9<10,"Low Buffer","Safe")) -> Low Buffer
A10: I009 | B10: Fruit Juice | C10: Beverages | D10: Non-Carbonated | E10: 120 | F10: 80 | G10: =E10-F10 -> 40 | H10: 40 | I10: FreshSip Distributors | J10: =IF(G10<H10, "Reorder","OK") -> OK | K10: =F10/G10 -> 2 | L10: =IF(K10>1.5,"Fast",IF(K10>=1,"Moderate","Slow")) -> Fast | M10: =G10-H10 -> 0 | N10: =IF(M10<0,"Critical",IF(M10<10,"Low Buffer","Safe")) -> Low Buffer
A11: I010 | B11: Tea Powder | C11: Grocery | D11: Hot Beverages | E11: 50 | F11: 15 | G11: =E11-F11 -> 35 | H11: 20 | I11: AssamLeaf Distributors | J11: =IF(G11<H11, "Reorder","OK") -> OK | K11: =F11/G11 -> 0.42857143 | L11: =IF(K11>1.5,"Fast",IF(K11>=1,"Moderate","Slow")) -> Slow | M11: =G11-H11 -> 15 | N11: =IF(M11<0,"Critical",IF(M11<10,"Low Buffer","Safe")) -> Safe
A12: I011 | B12: Salt | C12: Grocery | D12: Essentials | E12: 80 | F12: 20 | G12: =E12-F12 -> 60 | H12: 30 | I12: AgroFresh Supplies Pvt Ltd | J12: =IF(G12<H12, "Reorder","OK") -> OK | K12: =F12/G12 -> 0.33333333 | L12: =IF(K12>1.5,"Fast",IF(K12>=1,"Moderate","Slow")) -> Slow | M12: =G12-H12 -> 30 | N12: =IF(M12<0,"Critical",IF(M12<10,"Low Buffer","Safe")) -> Safe
A13: I012 | B13: Cooking Oil | C13: Grocery | D13: Edible Oils | E13: 60 | F13: 15 | G13: =E13-F13 -> 45 | H13: 20 | I13: AgroFresh Supplies Pvt Ltd | J13: =IF(G13<H13, "Reorder","OK") -> OK | K13: =F13/G13 -> 0.33333333 | L13: =IF(K13>1.5,"Fast",IF(K13>=1,"Moderate","Slow")) -> Slow | M13: =G13-H13 -> 25 | N13: =IF(M13<0,"Critical",IF(M13<10,"Low Buffer","Safe")) -> Safe
... A41: I040 | B41: Glass Cleaner | C41: Household | D41: Cleaning | E41: 100 | F41: 40 | G41: =E41-F41 -> 60 | H41: 20 | I41: SparkleClean Distributors | J41: =IF(G41<H41, "Reorder","OK") -> OK | K41: =F41/G41 -> 0.66666667 | L41: =IF(K41>1.5,"Fast",IF(K41>=1,"Moderate","Slow")) -> Slow | M41: =G41-H41 -> 40 | N41: =IF(M41<0,"Critical",IF(M41<10,"Low Buffer","Safe")) -> Safe
A47: Total Stock | B47: =SUM(G2:G41) -> 1925
A48: Total Items | B48: =COUNTA(A2:A41) -> 40
A49: Reorder Items | B49: =COUNTIF(J2:J41,"Reorder") -> 4

Sheet Calculations
A1: Rank | B1: Item ID | C1: Item Name | D1: Stock Out | E1: Stock Out % | F1: Cumulative % | G1: ABC Category | H1: Stock Status | I1: Reorder Priority
A2: =ROW()-1 -> 1 | B2: I030 | C2: Potatoes | D2: 95 | E2: =D2/SUM($D$2:$D$41) -> 0.046683047 | F2: =E2 -> 0.046683047 | G2: =IF(F2<0.7,"A",IF(F2<0.9,"B","C")) -> A | H2: =VLOOKUP(B2,'Raw Data'!A:J,10,FALSE) -> Reorder | I2: =IF(AND(G2="A", H2="Reorder"),"URGENT",IF(G2="A","High",IF(G2="B","Medium","Low"))) -> URGENT
A3: =ROW()-1 -> 2 | B3: I031 | C3: Onions | D3: 90 | E3: =D3/SUM($D$2:$D$41) -> 0.044226044 | F3: =F2+E3 -> 0.090909091 | G3: =IF(F3<0.7,"A",IF(F3<0.9,"B","C")) -> A | H3: =VLOOKUP(B3,'Raw Data'!A:J,10,FALSE) -> OK | I3: =IF(AND(G3="A", H3="Reorder"),"URGENT",IF(G3="A","High",IF(G3="B","Medium","Low"))) -> High
A4: =ROW()-1 -> 3 | B4: I009 | C4: Fruit Juice | D4: 80 | E4: =D4/SUM($D$2:$D$41) -> 0.039312039 | F4: =F3+E4 -> 0.13022113 | G4: =IF(F4<0.7,"A",IF(F4<0.9,"B","C")) -> A | H4: =VLOOKUP(B4,'Raw Data'!A:J,10,FALSE) -> OK | I4: =IF(AND(G4="A", H4="Reorder"),"URGENT",IF(G4="A","High",IF(G4="B","Medium","Low"))) -> High
A5: =ROW()-1 -> 4 | B5: I021 | C5: Handwash | D5: 80 | E5: =D5/SUM($D$2:$D$41) -> 0.039312039 | F5: =F4+E5 -> 0.16953317 | G5: =IF(F5<0.7,"A",IF(F5<0.9,"B","C")) -> A | H5: =VLOOKUP(B5,'Raw Data'!A:J,10,FALSE) -> OK | I5: =IF(AND(G5="A", H5="Reorder"),"URGENT",IF(G5="A","High",IF(G5="B","Medium","Low"))) -> High
A6: =ROW()-1 -> 5 | B6: 1017 | C6: Mineral Water | D6: 75 | E6: =D6/SUM($D$2:$D$41) -> 0.036855037 | F6: =F5+E6 -> 0.20638821 | G6: =IF(F6<0.7,"A",IF(F6<0.9,"B","C")) -> A | H6: =VLOOKUP('Monthly Demand Data'!A32,'Raw Data'!A:J,10,FALSE) -> OK | I6: =IF(AND(G6="A", H6="Reorder"),"URGENT",IF(G6="A","High",IF(G6="B","Medium","Low"))) -> High
A7: =ROW()-1 -> 6 | B7: I006 | C7: Eggs | D7: 70 | E7: =D7/SUM($D$2:$D$41) -> 0.034398034 | F7: =F6+E7 -> 0.24078624 | G7: =IF(F7<0.7,"A",IF(F7<0.9,"B","C")) -> A | H7: =VLOOKUP(B7,'Raw Data'!A:J,10,FALSE) -> OK | I7: =IF(AND(G7="A", H7="Reorder"),"URGENT",IF(G7="A","High",IF(G7="B","Medium","Low"))) -> High
A8: =ROW()-1 -> 7 | B8: I019 | C8: Frozen Chicken | D8: 70 | E8: =D8/SUM($D$2:$D$41) -> 0.034398034 | F8: =F7+E8 -> 0.27518428 | G8: =IF(F8<0.7,"A",IF(F8<0.9,"B","C")) -> A | H8: =VLOOKUP(B8,'Raw Data'!A:J,10,FALSE) -> OK | I8: =IF(AND(G8="A", H8="Reorder"),"URGENT",IF(G8="A","High",IF(G8="B","Medium","Low"))) -> High
A9: =ROW()-1 -> 8 | B9: I022 | C9: Detergent Powder | D9: 70 | E9: =D9/SUM($D$2:$D$41) -> 0.034398034 | F9: =F8+E9 -> 0.30958231 | G9: =IF(F9<0.7,"A",IF(F9<0.9,"B","C")) -> A | H9: =VLOOKUP(B9,'Raw Data'!A:J,10,FALSE) -> OK | I9: =IF(AND(G9="A", H9="Reorder"),"URGENT",IF(G9="A","High",IF(G9="B","Medium","Low"))) -> High
A10: =ROW()-1 -> 9 | B10: I024 | C10: Tissue Paper | D10: 70 | E10: =D10/SUM($D$2:$D$41) -> 0.034398034 | F10: =F9+E10 -> 0.34398034 | G10: =IF(F10<0.7,"A",IF(F10<0.9,"B","C")) -> A | H10: =VLOOKUP(B10,'Raw Data'!A:J,10,FALSE) -> OK | I10: =IF(AND(G10="A", H10="Reorder"),"URGENT",IF(G10="A","High",IF(G10="B","Medium","Low"))) -> High
A11: =ROW()-1 -> 10 | B11: I032 | C11: Bananas | D11: 70 | E11: =D11/SUM($D$2:$D$41) -> 0.034398034 | F11: =F10+E11 -> 0.37837838 | G11: =IF(F11<0.7,"A",IF(F11<0.9,"B","C")) -> A | H11: =VLOOKUP(B11,'Raw Data'!A:J,10,FALSE) -> OK | I11: =IF(AND(G11="A", H11="Reorder"),"URGENT",IF(G11="A","High",IF(G11="B","Medium","Low"))) -> High
A12: =ROW()-1 -> 11 | B12: I038 | C12: Spinach | D12: 70 | E12: =D12/SUM($D$2:$D$41) -> 0.034398034 | F12: =F11+E12 -> 0.41277641 | G12: =IF(F12<0.7,"A",IF(F12<0.9,"B","C")) -> A | H12: =VLOOKUP(B12,'Raw Data'!A:J,10,FALSE) -> Reorder | I12: =IF(AND(G12="A", H12="Reorder"),"URGENT",IF(G12="A","High",IF(G12="B","Medium","Low"))) -> URGENT
A13: =ROW()-1 -> 12 | B13: I020 | C13: Cheese | D13: 65 | E13: =D13/SUM($D$2:$D$41) -> 0.031941032 | F13: =F12+E13 -> 0.44471744 | G13: =IF(F13<0.7,"A",IF(F13<0.9,"B","C")) -> A | H13: =VLOOKUP(B13,'Raw Data'!A:J,10,FALSE) -> OK | I13: =IF(AND(G13="A", H13="Reorder"),"URGENT",IF(G13="A","High",IF(G13="B","Medium","Low"))) -> High
A14: =ROW()-1 -> 13 | B14: I036 | C14: Hand Sanitizer | D14: 65 | E14: =D14/SUM($D$2:$D$41) -> 0.031941032 | F14: =F13+E14 -> 0.47665848 | G14: =IF(F14<0.7,"A",IF(F14<0.9,"B","C")) -> A | H14: =VLOOKUP(B14,'Raw Data'!A:J,10,FALSE) -> OK | I14: =IF(AND(G14="A", H14="Reorder"),"URGENT",IF(G14="A","High",IF(G14="B","Medium","Low"))) -> High
A15: =ROW()-1 -> 14 | B15: I008 | C15: Chips | D15: 60 | E15: =D15/SUM($D$2:$D$41) -> 0.029484029 | F15: =F14+E15 -> 0.50614251 | G15: =IF(F15<0.7,"A",IF(F15<0.9,"B","C")) -> A | H15: =VLOOKUP(B15,'Raw Data'!A:J,10,FALSE) -> OK | I15: =IF(AND(G15="A", H15="Reorder"),"URGENT",IF(G15="A","High",IF(G15="B","Medium","Low"))) -> High
A16: =ROW()-1 -> 15 | B16: I016 | C16: Garbage Bags | D16: 60 | E16: =D16/SUM($D$2:$D$41) -> 0.029484029 | F16: =F15+E16 -> 0.53562654 | G16: =IF(F16<0.7,"A",IF(F16<0.9,"B","C")) -> A | H16: =VLOOKUP(B16,'Raw Data'!A:J,10,FALSE) -> OK | I16: =IF(AND(G16="A", H16="Reorder"),"URGENT",IF(G16="A","High",IF(G16="B","Medium","Low"))) -> High
A17: =ROW()-1 -> 16 | B17: I018 | C17: Chocolate | D17: 60 | E17: =D17/SUM($D$2:$D$41) -> 0.029484029 | F17: =F16+E17 -> 0.56511057 | G17: =IF(F17<0.7,"A",IF(F17<0.9,"B","C")) -> A | H17: =VLOOKUP(B17,'Raw Data'!A:J,10,FALSE) -> OK | I17: =IF(AND(G17="A", H17="Reorder"),"URGENT",IF(G17="A","High",IF(G17="B","Medium","Low"))) -> High
A18: =ROW()-1 -> 17 | B18: I023 | C18: Dishwash Liquid | D18: 60 | E18: =D18/SUM($D$2:$D$41) -> 0.029484029 | F18: =F17+E18 -> 0.59459459 | G18: =IF(F18<0.7,"A",IF(F18<0.9,"B","C")) -> A | H18: =VLOOKUP(B18,'Raw Data'!A:J,10,FALSE) -> OK | I18: =IF(AND(G18="A", H18="Reorder"),"URGENT",IF(G18="A","High",IF(G18="B","Medium","Low"))) -> High
... A41: =ROW()-1 -> 40 | B41: I002 | C41: Shampoo | D41: 10 | E41: =D41/SUM($D$2:$D$41) -> 0.0049140049 | F41: =F40+E41 -> 1 | G41: =IF(F41<0.7,"A",IF(F41<0.9,"B","C")) -> C | H41: =VLOOKUP(B41,'Raw Data'!A:J,10,FALSE) -> OK | I41: =IF(AND(G41="A", H41="Reorder"),"URGENT",IF(G41="A","High",IF(G41="B","Medium","Low"))) -> Low
